<?xml version="1.0" ?>
<robot name="spooder_URDF_try1" xmlns:xacro="http://www.ros.org/wiki/xacro">

<xacro:include filename="$(find spooder_URDF_try1_description)/urdf/materials.xacro" />
<xacro:include filename="$(find spooder_URDF_try1_description)/urdf/spooder_URDF_try1.trans" />
<xacro:include filename="$(find spooder_URDF_try1_description)/urdf/spooder_URDF_try1.gazebo" />
<link name="base_link">
  <inertial>
    <origin xyz="0.0004094187506667984 -0.0003098828110237046 0.006619110740130701" rpy="0 0 0"/>
    <mass value="0.682009335465891"/>
    <inertia ixx="0.000618" iyy="0.000621" izz="0.000995" ixy="2e-06" iyz="1e-06" ixz="-3e-06"/>
  </inertial>
  <visual>
    <origin xyz="0 0 0" rpy="0 0 0"/>
    <geometry>
      <mesh filename="package://spooder_URDF_try1_description/meshes/base_link.stl" scale="0.001 0.001 0.001"/>
    </geometry>
    <material name="silver"/>
  </visual>
  <collision>
    <origin xyz="0 0 0" rpy="0 0 0"/>
    <geometry>
      <mesh filename="package://spooder_URDF_try1_description/meshes/base_link.stl" scale="0.001 0.001 0.001"/>
    </geometry>
  </collision>
</link>

<link name="link_3_step_v1_6">
  <inertial>
    <origin xyz="0.001748684642474893 -2.880886217640488e-05 -0.019187896288379355" rpy="0 0 0"/>
    <mass value="0.013232579044312473"/>
    <inertia ixx="3e-06" iyy="3e-06" izz="0.0" ixy="0.0" iyz="-0.0" ixz="0.0"/>
  </inertial>
  <visual>
    <origin xyz="-0.052398 0.103956 -0.007488" rpy="0 0 0"/>
    <geometry>
      <mesh filename="package://spooder_URDF_try1_description/meshes/link_3_step_v1_6.stl" scale="0.001 0.001 0.001"/>
    </geometry>
    <material name="silver"/>
  </visual>
  <collision>
    <origin xyz="-0.052398 0.103956 -0.007488" rpy="0 0 0"/>
    <geometry>
      <mesh filename="package://spooder_URDF_try1_description/meshes/link_3_step_v1_6.stl" scale="0.001 0.001 0.001"/>
    </geometry>
  </collision>
</link>

<link name="link_3_step_v1_5">
  <inertial>
    <origin xyz="0.0008988284035516825 0.0014999999999995494 -0.019187681932123883" rpy="0 0 0"/>
    <mass value="0.013232579044312473"/>
    <inertia ixx="3e-06" iyy="3e-06" izz="0.0" ixy="0.0" iyz="0.0" ixz="0.0"/>
  </inertial>
  <visual>
    <origin xyz="-0.116228 0.0066 -0.007812" rpy="0 0 0"/>
    <geometry>
      <mesh filename="package://spooder_URDF_try1_description/meshes/link_3_step_v1_5.stl" scale="0.001 0.001 0.001"/>
    </geometry>
    <material name="silver"/>
  </visual>
  <collision>
    <origin xyz="-0.116228 0.0066 -0.007812" rpy="0 0 0"/>
    <geometry>
      <mesh filename="package://spooder_URDF_try1_description/meshes/link_3_step_v1_5.stl" scale="0.001 0.001 0.001"/>
    </geometry>
  </collision>
</link>

<link name="link_3_step_v1_4">
  <inertial>
    <origin xyz="-0.0008498562389234326 0.0015288088621762674 -0.01918768193212388" rpy="0 0 0"/>
    <mass value="0.013232579044312473"/>
    <inertia ixx="3e-06" iyy="3e-06" izz="0.0" ixy="-0.0" iyz="0.0" ixz="0.0"/>
  </inertial>
  <visual>
    <origin xyz="-0.06383 -0.097356 -0.007812" rpy="0 0 0"/>
    <geometry>
      <mesh filename="package://spooder_URDF_try1_description/meshes/link_3_step_v1_4.stl" scale="0.001 0.001 0.001"/>
    </geometry>
    <material name="silver"/>
  </visual>
  <collision>
    <origin xyz="-0.06383 -0.097356 -0.007812" rpy="0 0 0"/>
    <geometry>
      <mesh filename="package://spooder_URDF_try1_description/meshes/link_3_step_v1_4.stl" scale="0.001 0.001 0.001"/>
    </geometry>
  </collision>
</link>

<link name="link_3_step_v1_3">
  <inertial>
    <origin xyz="-0.001748684642474796 2.8808862176335492e-05 -0.01918768193212388" rpy="0 0 0"/>
    <mass value="0.013232579044312473"/>
    <inertia ixx="3e-06" iyy="3e-06" izz="0.0" ixy="0.0" iyz="0.0" ixz="-0.0"/>
  </inertial>
  <visual>
    <origin xyz="0.052398 -0.103956 -0.007812" rpy="0 0 0"/>
    <geometry>
      <mesh filename="package://spooder_URDF_try1_description/meshes/link_3_step_v1_3.stl" scale="0.001 0.001 0.001"/>
    </geometry>
    <material name="silver"/>
  </visual>
  <collision>
    <origin xyz="0.052398 -0.103956 -0.007812" rpy="0 0 0"/>
    <geometry>
      <mesh filename="package://spooder_URDF_try1_description/meshes/link_3_step_v1_3.stl" scale="0.001 0.001 0.001"/>
    </geometry>
  </collision>
</link>

<link name="link_3_step_v1_2">
  <inertial>
    <origin xyz="-0.0008988284035517102 -0.0014999999999994757 -0.01918768193212388" rpy="0 0 0"/>
    <mass value="0.013232579044312473"/>
    <inertia ixx="3e-06" iyy="3e-06" izz="0.0" ixy="0.0" iyz="-0.0" ixz="-0.0"/>
  </inertial>
  <visual>
    <origin xyz="0.116228 -0.0066 -0.007812" rpy="0 0 0"/>
    <geometry>
      <mesh filename="package://spooder_URDF_try1_description/meshes/link_3_step_v1_2.stl" scale="0.001 0.001 0.001"/>
    </geometry>
    <material name="silver"/>
  </visual>
  <collision>
    <origin xyz="0.116228 -0.0066 -0.007812" rpy="0 0 0"/>
    <geometry>
      <mesh filename="package://spooder_URDF_try1_description/meshes/link_3_step_v1_2.stl" scale="0.001 0.001 0.001"/>
    </geometry>
  </collision>
</link>

<link name="link_3_step_v1_1">
  <inertial>
    <origin xyz="0.0008498562389233494 -0.0015288088621762674 -0.01918789628837935" rpy="0 0 0"/>
    <mass value="0.013232579044312473"/>
    <inertia ixx="3e-06" iyy="3e-06" izz="0.0" ixy="-0.0" iyz="-0.0" ixz="-0.0"/>
  </inertial>
  <visual>
    <origin xyz="0.06383 0.097356 -0.007488" rpy="0 0 0"/>
    <geometry>
      <mesh filename="package://spooder_URDF_try1_description/meshes/link_3_step_v1_1.stl" scale="0.001 0.001 0.001"/>
    </geometry>
    <material name="silver"/>
  </visual>
  <collision>
    <origin xyz="0.06383 0.097356 -0.007488" rpy="0 0 0"/>
    <geometry>
      <mesh filename="package://spooder_URDF_try1_description/meshes/link_3_step_v1_1.stl" scale="0.001 0.001 0.001"/>
    </geometry>
  </collision>
</link>

<link name="link_2_step_v1_2">
  <inertial>
    <origin xyz="-0.040150116033654204 0.002290214494911128 -0.0007667164494134359" rpy="0 0 0"/>
    <mass value="0.07699887941450732"/>
    <inertia ixx="7e-06" iyy="1.6e-05" izz="1.5e-05" ixy="0.0" iyz="-0.0" ixz="-0.0"/>
  </inertial>
  <visual>
    <origin xyz="0.071228 -0.02255 -0.013462" rpy="0 0 0"/>
    <geometry>
      <mesh filename="package://spooder_URDF_try1_description/meshes/link_2_step_v1_2.stl" scale="0.001 0.001 0.001"/>
    </geometry>
    <material name="silver"/>
  </visual>
  <collision>
    <origin xyz="0.071228 -0.02255 -0.013462" rpy="0 0 0"/>
    <geometry>
      <mesh filename="package://spooder_URDF_try1_description/meshes/link_2_step_v1_2.stl" scale="0.001 0.001 0.001"/>
    </geometry>
  </collision>
</link>

<link name="link_2_step_v1_1">
  <inertial>
    <origin xyz="-0.022058314804874385 -0.03362617066334 -0.0007669308056689073" rpy="0 0 0"/>
    <mass value="0.07699887941450732"/>
    <inertia ixx="1.3e-05" iyy="1e-05" izz="1.5e-05" ixy="-4e-06" iyz="-0.0" ixz="0.0"/>
  </inertial>
  <visual>
    <origin xyz="0.055143 0.05041 -0.013138" rpy="0 0 0"/>
    <geometry>
      <mesh filename="package://spooder_URDF_try1_description/meshes/link_2_step_v1_1.stl" scale="0.001 0.001 0.001"/>
    </geometry>
    <material name="silver"/>
  </visual>
  <collision>
    <origin xyz="0.055143 0.05041 -0.013138" rpy="0 0 0"/>
    <geometry>
      <mesh filename="package://spooder_URDF_try1_description/meshes/link_2_step_v1_1.stl" scale="0.001 0.001 0.001"/>
    </geometry>
  </collision>
</link>

<link name="link_2_step_v1_6">
  <inertial>
    <origin xyz="0.01809180122877971 -0.03591638515825078 -0.0007669308056689108" rpy="0 0 0"/>
    <mass value="0.07699887941450732"/>
    <inertia ixx="1.4e-05" iyy="9e-06" izz="1.5e-05" ixy="4e-06" iyz="-0.0" ixz="0.0"/>
  </inertial>
  <visual>
    <origin xyz="-0.016085 0.07296 -0.013138" rpy="0 0 0"/>
    <geometry>
      <mesh filename="package://spooder_URDF_try1_description/meshes/link_2_step_v1_6.stl" scale="0.001 0.001 0.001"/>
    </geometry>
    <material name="silver"/>
  </visual>
  <collision>
    <origin xyz="-0.016085 0.07296 -0.013138" rpy="0 0 0"/>
    <geometry>
      <mesh filename="package://spooder_URDF_try1_description/meshes/link_2_step_v1_6.stl" scale="0.001 0.001 0.001"/>
    </geometry>
  </collision>
</link>

<link name="link_2_step_v1_5">
  <inertial>
    <origin xyz="0.04015011603365433 -0.002290214494911076 -0.0007667164494134238" rpy="0 0 0"/>
    <mass value="0.07699887941450732"/>
    <inertia ixx="7e-06" iyy="1.6e-05" izz="1.5e-05" ixy="0.0" iyz="0.0" ixz="0.0"/>
  </inertial>
  <visual>
    <origin xyz="-0.071228 0.02255 -0.013462" rpy="0 0 0"/>
    <geometry>
      <mesh filename="package://spooder_URDF_try1_description/meshes/link_2_step_v1_5.stl" scale="0.001 0.001 0.001"/>
    </geometry>
    <material name="silver"/>
  </visual>
  <collision>
    <origin xyz="-0.071228 0.02255 -0.013462" rpy="0 0 0"/>
    <geometry>
      <mesh filename="package://spooder_URDF_try1_description/meshes/link_2_step_v1_5.stl" scale="0.001 0.001 0.001"/>
    </geometry>
  </collision>
</link>

<link name="link_2_step_v1_4">
  <inertial>
    <origin xyz="0.02205831480487433 0.03362617066333994 -0.0007667164494134359" rpy="0 0 0"/>
    <mass value="0.07699887941450732"/>
    <inertia ixx="1.3e-05" iyy="1e-05" izz="1.5e-05" ixy="-4e-06" iyz="0.0" ixz="-0.0"/>
  </inertial>
  <visual>
    <origin xyz="-0.055143 -0.05041 -0.013462" rpy="0 0 0"/>
    <geometry>
      <mesh filename="package://spooder_URDF_try1_description/meshes/link_2_step_v1_4.stl" scale="0.001 0.001 0.001"/>
    </geometry>
    <material name="silver"/>
  </visual>
  <collision>
    <origin xyz="-0.055143 -0.05041 -0.013462" rpy="0 0 0"/>
    <geometry>
      <mesh filename="package://spooder_URDF_try1_description/meshes/link_2_step_v1_4.stl" scale="0.001 0.001 0.001"/>
    </geometry>
  </collision>
</link>

<link name="link_2_step_v1_3">
  <inertial>
    <origin xyz="-0.018091801228779677 0.03591638515825066 -0.0007667164494134359" rpy="0 0 0"/>
    <mass value="0.07699887941450732"/>
    <inertia ixx="1.4e-05" iyy="9e-06" izz="1.5e-05" ixy="4e-06" iyz="0.0" ixz="-0.0"/>
  </inertial>
  <visual>
    <origin xyz="0.016085 -0.07296 -0.013462" rpy="0 0 0"/>
    <geometry>
      <mesh filename="package://spooder_URDF_try1_description/meshes/link_2_step_v1_3.stl" scale="0.001 0.001 0.001"/>
    </geometry>
    <material name="silver"/>
  </visual>
  <collision>
    <origin xyz="0.016085 -0.07296 -0.013462" rpy="0 0 0"/>
    <geometry>
      <mesh filename="package://spooder_URDF_try1_description/meshes/link_2_step_v1_3.stl" scale="0.001 0.001 0.001"/>
    </geometry>
  </collision>
</link>

<link name="link_1_step_v1_5">
  <inertial>
    <origin xyz="0.025463633393486465 0.0008189828458177477 0.00017368460184622597" rpy="0 0 0"/>
    <mass value="0.07192771620879662"/>
    <inertia ixx="7e-06" iyy="8e-06" izz="8e-06" ixy="-0.0" iyz="-0.0" ixz="0.0"/>
  </inertial>
  <visual>
    <origin xyz="-0.043628 0.0051 -0.018112" rpy="0 0 0"/>
    <geometry>
      <mesh filename="package://spooder_URDF_try1_description/meshes/link_1_step_v1_5.stl" scale="0.001 0.001 0.001"/>
    </geometry>
    <material name="silver"/>
  </visual>
  <collision>
    <origin xyz="-0.043628 0.0051 -0.018112" rpy="0 0 0"/>
    <geometry>
      <mesh filename="package://spooder_URDF_try1_description/meshes/link_1_step_v1_5.stl" scale="0.001 0.001 0.001"/>
    </geometry>
  </collision>
</link>

<link name="link_1_step_v1_4">
  <inertial>
    <origin xyz="0.012022286306301897 0.022461601130629415 0.0001736846018462225" rpy="0 0 0"/>
    <mass value="0.07192771620879662"/>
    <inertia ixx="8e-06" iyy="7e-06" izz="8e-06" ixy="-0.0" iyz="-0.0" ixz="0.0"/>
  </inertial>
  <visual>
    <origin xyz="-0.026231 -0.035233 -0.018112" rpy="0 0 0"/>
    <geometry>
      <mesh filename="package://spooder_URDF_try1_description/meshes/link_1_step_v1_4.stl" scale="0.001 0.001 0.001"/>
    </geometry>
    <material name="silver"/>
  </visual>
  <collision>
    <origin xyz="-0.026231 -0.035233 -0.018112" rpy="0 0 0"/>
    <geometry>
      <mesh filename="package://spooder_URDF_try1_description/meshes/link_1_step_v1_4.stl" scale="0.001 0.001 0.001"/>
    </geometry>
  </collision>
</link>

<link name="link_1_step_v1_3">
  <inertial>
    <origin xyz="-0.013441347087184512 0.021642618284811586 0.0001736846018462225" rpy="0 0 0"/>
    <mass value="0.07192771620879662"/>
    <inertia ixx="8e-06" iyy="7e-06" izz="8e-06" ixy="0.0" iyz="0.0" ixz="0.0"/>
  </inertial>
  <visual>
    <origin xyz="0.017397 -0.040333 -0.018112" rpy="0 0 0"/>
    <geometry>
      <mesh filename="package://spooder_URDF_try1_description/meshes/link_1_step_v1_3.stl" scale="0.001 0.001 0.001"/>
    </geometry>
    <material name="silver"/>
  </visual>
  <collision>
    <origin xyz="0.017397 -0.040333 -0.018112" rpy="0 0 0"/>
    <geometry>
      <mesh filename="package://spooder_URDF_try1_description/meshes/link_1_step_v1_3.stl" scale="0.001 0.001 0.001"/>
    </geometry>
  </collision>
</link>

<link name="link_1_step_v1_2">
  <inertial>
    <origin xyz="-0.025463633393486437 -0.0008189828458177919 0.0001736846018462225" rpy="0 0 0"/>
    <mass value="0.07192771620879662"/>
    <inertia ixx="7e-06" iyy="8e-06" izz="8e-06" ixy="-0.0" iyz="0.0" ixz="-0.0"/>
  </inertial>
  <visual>
    <origin xyz="0.043628 -0.0051 -0.018112" rpy="0 0 0"/>
    <geometry>
      <mesh filename="package://spooder_URDF_try1_description/meshes/link_1_step_v1_2.stl" scale="0.001 0.001 0.001"/>
    </geometry>
    <material name="silver"/>
  </visual>
  <collision>
    <origin xyz="0.043628 -0.0051 -0.018112" rpy="0 0 0"/>
    <geometry>
      <mesh filename="package://spooder_URDF_try1_description/meshes/link_1_step_v1_2.stl" scale="0.001 0.001 0.001"/>
    </geometry>
  </collision>
</link>

<link name="link_1_step_v1_1">
  <inertial>
    <origin xyz="-0.01202228630630196 -0.02246160113062949 0.0001734702455907372" rpy="0 0 0"/>
    <mass value="0.07192771620879662"/>
    <inertia ixx="8e-06" iyy="7e-06" izz="8e-06" ixy="-0.0" iyz="0.0" ixz="-0.0"/>
  </inertial>
  <visual>
    <origin xyz="0.026231 0.035233 -0.017788" rpy="0 0 0"/>
    <geometry>
      <mesh filename="package://spooder_URDF_try1_description/meshes/link_1_step_v1_1.stl" scale="0.001 0.001 0.001"/>
    </geometry>
    <material name="silver"/>
  </visual>
  <collision>
    <origin xyz="0.026231 0.035233 -0.017788" rpy="0 0 0"/>
    <geometry>
      <mesh filename="package://spooder_URDF_try1_description/meshes/link_1_step_v1_1.stl" scale="0.001 0.001 0.001"/>
    </geometry>
  </collision>
</link>

<link name="link_1_step_v1_6">
  <inertial>
    <origin xyz="0.013441347087184547 -0.021642618284811684 0.0001734702455907372" rpy="0 0 0"/>
    <mass value="0.07192771620879662"/>
    <inertia ixx="8e-06" iyy="7e-06" izz="8e-06" ixy="0.0" iyz="-0.0" ixz="-0.0"/>
  </inertial>
  <visual>
    <origin xyz="-0.017397 0.040333 -0.017788" rpy="0 0 0"/>
    <geometry>
      <mesh filename="package://spooder_URDF_try1_description/meshes/link_1_step_v1_6.stl" scale="0.001 0.001 0.001"/>
    </geometry>
    <material name="silver"/>
  </visual>
  <collision>
    <origin xyz="-0.017397 0.040333 -0.017788" rpy="0 0 0"/>
    <geometry>
      <mesh filename="package://spooder_URDF_try1_description/meshes/link_1_step_v1_6.stl" scale="0.001 0.001 0.001"/>
    </geometry>
  </collision>
</link>

<joint name="Revolute 1" type="revolute">
  <origin xyz="0.036313 -0.030996 -0.00565" rpy="0 0 0"/>
  <parent link="link_2_step_v1_6"/>
  <child link="link_3_step_v1_6"/>
  <axis xyz="0.866025 0.5 0.0"/>
  <limit upper="0.785398" lower="-0.785398" effort="100" velocity="100"/>
</joint>

<joint name="Revolute 2" type="revolute">
  <origin xyz="0.045 0.01595 -0.00565" rpy="0 0 0"/>
  <parent link="link_2_step_v1_5"/>
  <child link="link_3_step_v1_5"/>
  <axis xyz="-0.0 1.0 0.0"/>
  <limit upper="0.785398" lower="-0.785398" effort="100" velocity="100"/>
</joint>

<joint name="Revolute 3" type="revolute">
  <origin xyz="0.008687 0.046946 -0.00565" rpy="0 0 0"/>
  <parent link="link_2_step_v1_4"/>
  <child link="link_3_step_v1_4"/>
  <axis xyz="-0.866025 0.5 0.0"/>
  <limit upper="0.785398" lower="-0.785398" effort="100" velocity="100"/>
</joint>

<joint name="Revolute 4" type="revolute">
  <origin xyz="-0.036313 0.030996 -0.00565" rpy="0 0 0"/>
  <parent link="link_2_step_v1_3"/>
  <child link="link_3_step_v1_3"/>
  <axis xyz="-0.866025 -0.5 0.0"/>
  <limit upper="0.785398" lower="-0.785398" effort="100" velocity="100"/>
</joint>

<joint name="Revolute 5" type="revolute">
  <origin xyz="-0.045 -0.01595 -0.00565" rpy="0 0 0"/>
  <parent link="link_2_step_v1_2"/>
  <child link="link_3_step_v1_2"/>
  <axis xyz="0.0 -1.0 0.0"/>
  <limit upper="0.785398" lower="-0.785398" effort="100" velocity="100"/>
</joint>

<joint name="Revolute 6" type="revolute">
  <origin xyz="-0.008687 -0.046946 -0.00565" rpy="0 0 0"/>
  <parent link="link_2_step_v1_1"/>
  <child link="link_3_step_v1_1"/>
  <axis xyz="0.866025 -0.5 0.0"/>
  <limit upper="0.785398" lower="-0.785398" effort="100" velocity="100"/>
</joint>

<joint name="Revolute 7" type="revolute">
  <origin xyz="-0.0276 0.01745 -0.00465" rpy="0 0 0"/>
  <parent link="link_1_step_v1_2"/>
  <child link="link_2_step_v1_2"/>
  <axis xyz="-0.0 1.0 -0.0"/>
  <limit upper="0.785398" lower="-0.785398" effort="100" velocity="100"/>
</joint>

<joint name="Revolute 8" type="revolute">
  <origin xyz="-0.028912 -0.015177 -0.00465" rpy="0 0 0"/>
  <parent link="link_1_step_v1_1"/>
  <child link="link_2_step_v1_1"/>
  <axis xyz="-0.866025 0.5 -0.0"/>
  <limit upper="0.785398" lower="-0.785398" effort="100" velocity="100"/>
</joint>

<joint name="Revolute 9" type="revolute">
  <origin xyz="-0.001312 -0.032627 -0.00465" rpy="0 0 0"/>
  <parent link="link_1_step_v1_6"/>
  <child link="link_2_step_v1_6"/>
  <axis xyz="-0.866025 -0.5 -0.0"/>
  <limit upper="0.785398" lower="-0.785398" effort="100" velocity="100"/>
</joint>

<joint name="Revolute 10" type="revolute">
  <origin xyz="0.0276 -0.01745 -0.00465" rpy="0 0 0"/>
  <parent link="link_1_step_v1_5"/>
  <child link="link_2_step_v1_5"/>
  <axis xyz="0.0 -1.0 -0.0"/>
  <limit upper="0.785398" lower="-0.785398" effort="100" velocity="100"/>
</joint>

<joint name="Revolute 11" type="revolute">
  <origin xyz="0.028912 0.015177 -0.00465" rpy="0 0 0"/>
  <parent link="link_1_step_v1_4"/>
  <child link="link_2_step_v1_4"/>
  <axis xyz="0.866025 -0.5 -0.0"/>
  <limit upper="0.785398" lower="-0.785398" effort="100" velocity="100"/>
</joint>

<joint name="Revolute 12" type="revolute">
  <origin xyz="0.001312 0.032627 -0.00465" rpy="0 0 0"/>
  <parent link="link_1_step_v1_3"/>
  <child link="link_2_step_v1_3"/>
  <axis xyz="0.866025 0.5 -0.0"/>
  <limit upper="0.785398" lower="-0.785398" effort="100" velocity="100"/>
</joint>

<joint name="Revolute 17" type="revolute">
  <origin xyz="0.043628 -0.0051 0.018112" rpy="0 0 0"/>
  <parent link="base_link"/>
  <child link="link_1_step_v1_5"/>
  <axis xyz="-0.0 -0.0 1.0"/>
  <limit upper="0.785398" lower="-0.785398" effort="100" velocity="100"/>
</joint>

<joint name="Revolute 18" type="revolute">
  <origin xyz="0.026231 0.035233 0.018112" rpy="0 0 0"/>
  <parent link="base_link"/>
  <child link="link_1_step_v1_4"/>
  <axis xyz="-0.0 -0.0 1.0"/>
  <limit upper="0.785398" lower="-0.785398" effort="100" velocity="100"/>
</joint>

<joint name="Revolute 19" type="revolute">
  <origin xyz="-0.017397 0.040333 0.018112" rpy="0 0 0"/>
  <parent link="base_link"/>
  <child link="link_1_step_v1_3"/>
  <axis xyz="0.0 -0.0 1.0"/>
  <limit upper="0.785398" lower="-0.785398" effort="100" velocity="100"/>
</joint>

<joint name="Revolute 20" type="revolute">
  <origin xyz="-0.043628 0.0051 0.018112" rpy="0 0 0"/>
  <parent link="base_link"/>
  <child link="link_1_step_v1_2"/>
  <axis xyz="0.0 -0.0 1.0"/>
  <limit upper="0.785398" lower="-0.785398" effort="100" velocity="100"/>
</joint>

<joint name="Revolute 21" type="revolute">
  <origin xyz="-0.026231 -0.035233 0.017788" rpy="0 0 0"/>
  <parent link="base_link"/>
  <child link="link_1_step_v1_1"/>
  <axis xyz="0.0 0.0 1.0"/>
  <limit upper="0.785398" lower="-0.785398" effort="100" velocity="100"/>
</joint>

<joint name="Revolute 22" type="revolute">
  <origin xyz="0.017397 -0.040333 0.017788" rpy="0 0 0"/>
  <parent link="base_link"/>
  <child link="link_1_step_v1_6"/>
  <axis xyz="-0.0 0.0 1.0"/>
  <limit upper="0.785398" lower="-0.785398" effort="100" velocity="100"/>
</joint>

</robot>
